Workbook

Sheet Summary
A1: Room rent audit
A2: September 9, 2026 advertised-price snapshot; classifications reviewed September 20.
A4: Campus / distance | B4: Room listings | C4: Low-price sum | D4: High-price sum | E4: Average low | F4: Average high | G4: Mean midpoint
A5: Main 0-1 mi | B5: ='Main 0-1 mi'!B24 | C5: ='Main 0-1 mi'!B25 | D5: ='Main 0-1 mi'!C25 | E5: ='Main 0-1 mi'!B26 | F5: ='Main 0-1 mi'!C26 | G5: ='Main 0-1 mi'!D26
A6: Main 1-3 mi | B6: ='Main 1-3 mi'!B52 | C6: ='Main 1-3 mi'!B53 | D6: ='Main 1-3 mi'!C53 | E6: ='Main 1-3 mi'!B54 | F6: ='Main 1-3 mi'!C54 | G6: ='Main 1-3 mi'!D54
A7: Main 3-5 mi | B7: ='Main 3-5 mi'!B16 | C7: ='Main 3-5 mi'!B17 | D7: ='Main 3-5 mi'!C17 | E7: ='Main 3-5 mi'!B18 | F7: ='Main 3-5 mi'!C18 | G7: ='Main 3-5 mi'!D18
A8: Main Campus total | B8: =SUM(B5:B7) | C8: =SUM(C5:C7) | D8: =SUM(D5:D7) | E8: =C8/B8 | F8: =D8/B8 | G8: =(E8+F8)/2
A9: Centennial 0-1 mi | B9: ='Centennial 0-1 mi'!B14 | C9: ='Centennial 0-1 mi'!B15 | D9: ='Centennial 0-1 mi'!C15 | E9: ='Centennial 0-1 mi'!B16 | F9: ='Centennial 0-1 mi'!C16 | G9: ='Centennial 0-1 mi'!D16
A10: Centennial 1-3 mi | B10: ='Centennial 1-3 mi'!B59 | C10: ='Centennial 1-3 mi'!B60 | D10: ='Centennial 1-3 mi'!C60 | E10: ='Centennial 1-3 mi'!B61 | F10: ='Centennial 1-3 mi'!C61 | G10: ='Centennial 1-3 mi'!D61
A11: Centennial 3-5 mi | B11: ='Centennial 3-5 mi'!B19 | C11: ='Centennial 3-5 mi'!B20 | D11: ='Centennial 3-5 mi'!C20 | E11: ='Centennial 3-5 mi'!B21 | F11: ='Centennial 3-5 mi'!C21 | G11: ='Centennial 3-5 mi'!D21
A12: Centennial Campus total | B12: =SUM(B9:B11) | C12: =SUM(C9:C11) | D12: =SUM(D9:D11) | E12: =C12/B12 | F12: =D12/B12 | G12: =(E12+F12)/2
A13: Biomedical 0-1 mi | B13: ='Biomedical 0-1 mi'!B10 | C13: ='Biomedical 0-1 mi'!B11 | D13: ='Biomedical 0-1 mi'!C11 | E13: ='Biomedical 0-1 mi'!B12 | F13: ='Biomedical 0-1 mi'!C12 | G13: ='Biomedical 0-1 mi'!D12
A14: Biomedical 1-3 mi | B14: ='Biomedical 1-3 mi'!B44 | C14: ='Biomedical 1-3 mi'!B45 | D14: ='Biomedical 1-3 mi'!C45 | E14: ='Biomedical 1-3 mi'!B46 | F14: ='Biomedical 1-3 mi'!C46 | G14: ='Biomedical 1-3 mi'!D46
A15: Biomedical 3-5 mi | B15: ='Biomedical 3-5 mi'!B34 | C15: ='Biomedical 3-5 mi'!B35 | D15: ='Biomedical 3-5 mi'!C35 | E15: ='Biomedical 3-5 mi'!B36 | F15: ='Biomedical 3-5 mi'!C36 | G15: ='Biomedical 3-5 mi'!D36
A16: Biomedical Campus total | B16: =SUM(B13:B15) | C16: =SUM(C13:C15) | D16: =SUM(D13:D15) | E16: =C16/B16 | F16: =D16/B16 | G16: =(E16+F16)/2
A18: Article check | B18: Main Campus: 18 + 46 + 10 = 74 listings; mean midpoint = $868.53, displayed as about $869.
A19: Scope | B19: Room/per-bedroom advertised offers within five miles of at least one campus point. Campus areas overlap; do not add campus totals.
A20: Price note | B20: Advertised prices may exclude utilities and fees. Each listing receives equal weight.

Sheet Main all three bands (74)
A1: Main Campus all three bands — 74 room listings
A2: Sept. 9, 2026 advertised-price snapshot. Exact Main Campus all-bands view used to verify the article interactive. One vote per listing; midpoint=(low+high)/2.
A4: Listing name | B4: Low ($/month) | C4: High ($/month) | D4: Midpoint ($/month) | E4: Distance (mi) | F4: Band | G4: Listing ID | H4: Source URL
A5: "Avery Close " condos room available across from Centennial Campus NCSU NC State Raleigh | B5: 750 | C5: 750 | D5: =(B5+C5)/2 | E5: 0.3760481 | F5: 0-1 mi | G5: ocpsnmx4w4 | H5: https://offcampus.dasa.ncsu.edu/housing/property/avery-close-condos-room-available-across-from-centennial-campus-ncsu-nc-state-raleigh/ocpsnmx4w4
A6: $3600 saving on 2*2 Sublet at Stanhope Apartment for NC STATE | B6: 550 | C6: 550 | D6: =(B6+C6)/2 | E6: 0.70246811 | F6: 0-1 mi | G6: ocpd9wnxdk | H6: https://offcampus.dasa.ncsu.edu/housing/property/3600-saving-on-2-2-sublet-at-stanhope-apartment-for-nc-state/ocpd9wnxdk
A7: 105 Friendly Drive! Furnished Room Rentals with Utilities! | B7: 775 | C7: 1050 | D7: =(B7+C7)/2 | E7: 0.7343022 | F7: 0-1 mi | G7: ocphdtdgk2 | H7: https://offcampus.dasa.ncsu.edu/housing/property/105-friendly-drive-furnished-room-rentals-with-utilities/ocphdtdgk2
A8: 4BR/4BA Condo| On Wolfline | Preleasing 27-28 Special $850 Util/Parking Incld | Mile to Campus | B8: 875 | C8: 875 | D8: =(B8+C8)/2 | E8: 0.65541144 | F8: 0-1 mi | G8: ocpxdxd79p | H8: https://offcampus.dasa.ncsu.edu/housing/property/4br-4ba-condo-on-wolfline-preleasing-27-28-special-850-util-parking-incld-mile-to-campus/ocpxdxd79p
A9: Affordable Student Housing 1 Block from Campus on Wolf Line | B9: 640 | C9: 640 | D9: =(B9+C9)/2 | E9: 0.44340465 | F9: 0-1 mi | G9: ocph8n0fc0 | H9: https://offcampus.dasa.ncsu.edu/housing/property/affordable-student-housing-1-block-from-campus-on-wolf-line/ocph8n0fc0
A10: Big Promotion w/best price ever. Move in Immediately . MarcomTowns. Great location nice | B10: 950 | C10: 950 | D10: =(B10+C10)/2 | E10: 0.24348937 | F10: 0-1 mi | G10: ocpe1n95cm | H10: https://offcampus.dasa.ncsu.edu/housing/property/big-promotion-w-best-price-ever-move-in-immediately-marcomtowns-great-location-nice/ocpe1n95cm
A11: Brickside | B11: 999 | C11: 1825 | D11: =(B11+C11)/2 | E11: 0.90787619 | F11: 0-1 mi | G11: 75medjw | H11: https://offcampus.dasa.ncsu.edu/housing/property/brickside/75medjw
A12: Burt Drive Townhouses---Brand New Luxury Housing within walking distance to NCSU | B12: 1050 | C12: 1050 | D12: =(B12+C12)/2 | E12: 0.33988746 | F12: 0-1 mi | G12: ocpm68s5sh | H12: https://offcampus.dasa.ncsu.edu/housing/property/burt-drive-townhouses-brand-new-luxury-housing-within-walking-distance-to-ncsu/ocpm68s5sh
A13: College Inn | B13: 859 | C13: 1275 | D13: =(B13+C13)/2 | E13: 0.24646078 | F13: 0-1 mi | G13: se736e5 | H13: https://offcampus.dasa.ncsu.edu/housing/property/college-inn/se736e5
A14: Collegeview Duplex--Brand New Luxury Housing within walking distance to NCSU | B14: 900 | C14: 950 | D14: =(B14+C14)/2 | E14: 0.24915253 | F14: 0-1 mi | G14: ocppjxdd3r | H14: https://offcampus.dasa.ncsu.edu/housing/property/collegeview-duplex-brand-new-luxury-housing-within-walking-distance-to-ncsu/ocppjxdd3r
A15: Convenient Kaplan Dr property near NCSU buses, park, grocery, with parking space & private bathroom | B15: 675 | C15: 675 | D15: =(B15+C15)/2 | E15: 0.71685512 | F15: 0-1 mi | G15: ocp5lwrmvq | H15: https://offcampus.dasa.ncsu.edu/housing/property/convenient-kaplan-dr-property-near-ncsu-buses-park-grocery-with-parking-space-and-private-bathroom/ocp5lwrmvq
A16: Reavis ---Brand New Luxury Housing within walking distance to NCSU | B16: 925 | C16: 975 | D16: =(B16+C16)/2 | E16: 0.84607921 | F16: 0-1 mi | G16: ocpvlydr3e | H16: https://offcampus.dasa.ncsu.edu/housing/property/reavis-brand-new-luxury-housing-within-walking-distance-to-ncsu/ocpvlydr3e
... A78: Room in Townhome on Macedonia Lake Dr | B78: 800 | C78: 800 | D78: =(B78+C78)/2 | E78: 4.036728 | F78: 3-5 mi | G78: 9m73sq5 | H78: https://offcampus.dasa.ncsu.edu/housing/property/room-in-townhome-on-macedonia-lake-dr/9m73sq5
A81: Prices used (COUNT) | B81: =COUNT(B5:B78) | C81: =COUNT(C5:C78) | D81: =COUNT(D5:D78)
A82: Total advertised rent (SUM) | B82: =SUM(B5:B78) | C82: =SUM(C5:C78) | D82: =SUM(D5:D78)
A83: Average (sum / count) | B83: =B82/B81 | C83: =C82/C81 | D83: =D82/D81
A84: Median listing midpoint | D84: =MEDIAN(D5:D78)
A87: Main Campus band | B87: Listings | C87: Low-price sum | D87: High-price sum | E87: Midpoint sum | F87: Mean midpoint
A88: 0-1 mi | B88: =COUNTIF($F$5:$F78,A88) | C88: =SUMIF($F$5:$F78,A88,$B$5:$B78) | D88: =SUMIF($F$5:$F78,A88,$C$5:$C78) | E88: =SUMIF($F$5:$F78,A88,$D$5:$D78) | F88: =E88/B88
A89: 1-3 mi | B89: =COUNTIF($F$5:$F78,A89) | C89: =SUMIF($F$5:$F78,A89,$B$5:$B78) | D89: =SUMIF($F$5:$F78,A89,$C$5:$C78) | E89: =SUMIF($F$5:$F78,A89,$D$5:$D78) | F89: =E89/B89
A90: 3-5 mi | B90: =COUNTIF($F$5:$F78,A90) | C90: =SUMIF($F$5:$F78,A90,$B$5:$B78) | D90: =SUMIF($F$5:$F78,A90,$C$5:$C78) | E90: =SUMIF($F$5:$F78,A90,$D$5:$D78) | F90: =E90/B90
A91: All three bands | B91: =SUM(B88:B90) | C91: =SUM(C88:C90) | D91: =SUM(D88:D90) | E91: =SUM(E88:E90) | F91: =E91/B91
A94: Draft page check | B94: Rounded average low | C94: Rounded average high | D94: Rounded midpoint
A95: Displayed values | B95: =ROUND(B83,0) | C95: =ROUND(C83,0) | D95: =ROUND(D83,0)

Sheet Main 0-1 mi
A1: Main 0-1 mi
A2: Sept. 9, 2026 advertised-price snapshot. One vote per listing; midpoint=(low+high)/2.
A4: Listing name | B4: Low ($/month) | C4: High ($/month) | D4: Midpoint ($/month) | E4: Distance (mi) | F4: Listing ID | G4: Source URL
A5: "Avery Close " condos room available across from Centennial Campus NCSU NC State Raleigh | B5: 750 | C5: 750 | D5: =(B5+C5)/2 | E5: 0.3760481 | F5: ocpsnmx4w4 | G5: https://offcampus.dasa.ncsu.edu/housing/property/avery-close-condos-room-available-across-from-centennial-campus-ncsu-nc-state-raleigh/ocpsnmx4w4
A6: $3600 saving on 2*2 Sublet at Stanhope Apartment for NC STATE | B6: 550 | C6: 550 | D6: =(B6+C6)/2 | E6: 0.70246811 | F6: ocpd9wnxdk | G6: https://offcampus.dasa.ncsu.edu/housing/property/3600-saving-on-2-2-sublet-at-stanhope-apartment-for-nc-state/ocpd9wnxdk
A7: 105 Friendly Drive! Furnished Room Rentals with Utilities! | B7: 775 | C7: 1050 | D7: =(B7+C7)/2 | E7: 0.7343022 | F7: ocphdtdgk2 | G7: https://offcampus.dasa.ncsu.edu/housing/property/105-friendly-drive-furnished-room-rentals-with-utilities/ocphdtdgk2
A8: 4BR/4BA Condo| On Wolfline | Preleasing 27-28 Special $850 Util/Parking Incld | Mile to Campus | B8: 875 | C8: 875 | D8: =(B8+C8)/2 | E8: 0.65541144 | F8: ocpxdxd79p | G8: https://offcampus.dasa.ncsu.edu/housing/property/4br-4ba-condo-on-wolfline-preleasing-27-28-special-850-util-parking-incld-mile-to-campus/ocpxdxd79p
A9: Affordable Student Housing 1 Block from Campus on Wolf Line | B9: 640 | C9: 640 | D9: =(B9+C9)/2 | E9: 0.44340465 | F9: ocph8n0fc0 | G9: https://offcampus.dasa.ncsu.edu/housing/property/affordable-student-housing-1-block-from-campus-on-wolf-line/ocph8n0fc0
A10: Big Promotion w/best price ever. Move in Immediately . MarcomTowns. Great location nice | B10: 950 | C10: 950 | D10: =(B10+C10)/2 | E10: 0.24348937 | F10: ocpe1n95cm | G10: https://offcampus.dasa.ncsu.edu/housing/property/big-promotion-w-best-price-ever-move-in-immediately-marcomtowns-great-location-nice/ocpe1n95cm
A11: Brickside | B11: 999 | C11: 1825 | D11: =(B11+C11)/2 | E11: 0.90787619 | F11: 75medjw | G11: https://offcampus.dasa.ncsu.edu/housing/property/brickside/75medjw
A12: Burt Drive Townhouses---Brand New Luxury Housing within walking distance to NCSU | B12: 1050 | C12: 1050 | D12: =(B12+C12)/2 | E12: 0.33988746 | F12: ocpm68s5sh | G12: https://offcampus.dasa.ncsu.edu/housing/property/burt-drive-townhouses-brand-new-luxury-housing-within-walking-distance-to-ncsu/ocpm68s5sh
A13: College Inn | B13: 859 | C13: 1275 | D13: =(B13+C13)/2 | E13: 0.24646078 | F13: se736e5 | G13: https://offcampus.dasa.ncsu.edu/housing/property/college-inn/se736e5
A14: Collegeview Duplex--Brand New Luxury Housing within walking distance to NCSU | B14: 900 | C14: 950 | D14: =(B14+C14)/2 | E14: 0.24915253 | F14: ocppjxdd3r | G14: https://offcampus.dasa.ncsu.edu/housing/property/collegeview-duplex-brand-new-luxury-housing-within-walking-distance-to-ncsu/ocppjxdd3r
A15: Convenient Kaplan Dr property near NCSU buses, park, grocery, with parking space & private bathroom | B15: 675 | C15: 675 | D15: =(B15+C15)/2 | E15: 0.71685512 | F15: ocp5lwrmvq | G15: https://offcampus.dasa.ncsu.edu/housing/property/convenient-kaplan-dr-property-near-ncsu-buses-park-grocery-with-parking-space-and-private-bathroom/ocp5lwrmvq
A16: Reavis ---Brand New Luxury Housing within walking distance to NCSU | B16: 925 | C16: 975 | D16: =(B16+C16)/2 | E16: 0.84607921 | F16: ocpvlydr3e | G16: https://offcampus.dasa.ncsu.edu/housing/property/reavis-brand-new-luxury-housing-within-walking-distance-to-ncsu/ocpvlydr3e
... A22: Valentine Commons | B22: 1000 | C22: 1300 | D22: =(B22+C22)/2 | E22: 0.63600664 | F22: ocp5cx5drn | G22: https://offcampus.dasa.ncsu.edu/housing/property/valentine-commons/ocp5cx5drn
A24: Prices used (COUNT) | B24: =COUNT(B5:B22) | C24: =COUNT(C5:C22) | D24: =COUNT(D5:D22)
A25: Total advertised rent (SUM) | B25: =SUM(B5:B22) | C25: =SUM(C5:C22) | D25: =SUM(D5:D22)
A26: Average (sum / count) | B26: =B25/B24 | C26: =C25/C24 | D26: =D25/D24
A27: Median listing midpoint | D27: =MEDIAN(D5:D22)

Sheet Main 1-3 mi
A1: Main 1-3 mi
A2: Sept. 9, 2026 advertised-price snapshot. One vote per listing; midpoint=(low+high)/2.
A4: Listing name | B4: Low ($/month) | C4: High ($/month) | D4: Midpoint ($/month) | E4: Distance (mi) | F4: Listing ID | G4: Source URL
A5: 1st Month FREE! | B5: 625 | C5: 625 | D5: =(B5+C5)/2 | E5: 2.2158507 | F5: ocpq292qyw | G5: https://offcampus.dasa.ncsu.edu/housing/property/1st-month-free/ocpq292qyw
A6: 4bed 4bath Apartment Near Centennial Campus | B6: 725 | C6: 725 | D6: =(B6+C6)/2 | E6: 1.5903193 | F6: ocpsq86tm4 | G6: https://offcampus.dasa.ncsu.edu/housing/property/4bed-4bath-apartment-near-centennial-campus/ocpsq86tm4
A7: 5 bedroom townhome available near NC State | B7: 650 | C7: 650 | D7: =(B7+C7)/2 | E7: 2.3752356 | F7: ocppbmmgnt | G7: https://offcampus.dasa.ncsu.edu/housing/property/5-bedroom-townhome-available-near-nc-state/ocppbmmgnt
A8: All Girls Unit - Room with Private Bathroom at University Woods at Centennial Condominiums | B8: 645 | C8: 645 | D8: =(B8+C8)/2 | E8: 2.1883475 | F8: ocpjeweyz6 | G8: https://offcampus.dasa.ncsu.edu/housing/property/all-girls-unit-room-with-private-bathroom-at-university-woods-at-centennial-condominiums/ocpjeweyz6
A9: An apartments with 3 bed and 3 bath for NC State Students www.ncstudentsliving.com | B9: 650 | C9: 650 | D9: =(B9+C9)/2 | E9: 2.2620005 | F9: ocp0psn632 | G9: https://offcampus.dasa.ncsu.edu/housing/property/an-apartments-with-3-bed-and-3-bath-for-nc-state-students-www-ncstudentsliving-com/ocp0psn632
A10: Apartment close to NCSU | B10: 645 | C10: 645 | D10: =(B10+C10)/2 | E10: 1.6533172 | F10: ocpq99qjpx | G10: https://offcampus.dasa.ncsu.edu/housing/property/apartment-close-to-ncsu/ocpq99qjpx
A11: Campus Crossings Raleigh | B11: 685 | C11: 870 | D11: =(B11+C11)/2 | E11: 2.420199 | F11: z8cfdjw | G11: https://offcampus.dasa.ncsu.edu/housing/property/campus-crossings-raleigh/z8cfdjw
A12: Campus Crossings Raleigh | B12: 865 | C12: 865 | D12: =(B12+C12)/2 | E12: 2.3750998 | F12: ocp176ghy4 | G12: https://offcampus.dasa.ncsu.edu/housing/property/campus-crossings-raleigh/ocp176ghy4
A13: Campus West at Tryon | B13: 699 | C13: 699 | D13: =(B13+C13)/2 | E13: 2.8741204 | F13: 0pm7tt3 | G13: https://offcampus.dasa.ncsu.edu/housing/property/campus-west-at-tryon/0pm7tt3
A14: Centennial Ridge Student Housing | B14: 599 | C14: 2157 | D14: =(B14+C14)/2 | E14: 2.3721447 | F14: 7e6kx1w | G14: https://offcampus.dasa.ncsu.edu/housing/property/centennial-ridge-student-housing/7e6kx1w
A15: Condo near NCSU | B15: 800 | C15: 800 | D15: =(B15+C15)/2 | E15: 1.6254324 | F15: ocpx51p4tm | G15: https://offcampus.dasa.ncsu.edu/housing/property/condo-near-ncsu/ocpx51p4tm
A16: Cozy house 10 min walk to campus | B16: 1500 | C16: 1500 | D16: =(B16+C16)/2 | E16: 1.2587581 | F16: ocphycq162 | G16: https://offcampus.dasa.ncsu.edu/housing/property/cozy-house-10-min-walk-to-campus/ocphycq162
... A50: We have 1 bedroom open In a luxury 5 bed 5 full bath house 1/1/27-6/30/27 | B50: 1200 | C50: 1200 | D50: =(B50+C50)/2 | E50: 1.6347044 | F50: ocp6wsb4yt | G50: https://offcampus.dasa.ncsu.edu/housing/property/we-have-1-bedroom-open-in-a-luxury-5-bed-5-full-bath-house-1-1-27-6-30-27/ocp6wsb4yt
A52: Prices used (COUNT) | B52: =COUNT(B5:B50) | C52: =COUNT(C5:C50) | D52: =COUNT(D5:D50)
A53: Total advertised rent (SUM) | B53: =SUM(B5:B50) | C53: =SUM(C5:C50) | D53: =SUM(D5:D50)
A54: Average (sum / count) | B54: =B53/B52 | C54: =C53/C52 | D54: =D53/D52
A55: Median listing midpoint | D55: =MEDIAN(D5:D50)

Sheet Main 3-5 mi
A1: Main 3-5 mi
A2: Sept. 9, 2026 advertised-price snapshot. One vote per listing; midpoint=(low+high)/2.
A4: Listing name | B4: Low ($/month) | C4: High ($/month) | D4: Midpoint ($/month) | E4: Distance (mi) | F4: Listing ID | G4: Source URL
A5: 2850 Sanderford Rd (Raleigh, NC) | B5: 650 | C5: 650 | D5: =(B5+C5)/2 | E5: 4.7729169 | F5: lpl9fce | G5: https://offcampus.dasa.ncsu.edu/housing/property/2850-sanderford-rd-raleigh-nc/lpl9fce
A6: Brand New Luxury Furnished Townhome | 4 Bed / 3.5 Bath | 5 Min to NC State & 3 Mins to Fenton +shop | B6: 900 | C6: 1050 | D6: =(B6+C6)/2 | E6: 3.334997 | F6: ocpw46rjcl | G6: https://offcampus.dasa.ncsu.edu/housing/property/brand-new-luxury-furnished-townhome-4-bed-3-5-bath-5-min-to-nc-state-and-3-mins-to-fenton-shop/ocpw46rjcl
A7: Brick Bungalow close to Campus | B7: 1050 | C7: 1050 | D7: =(B7+C7)/2 | E7: 3.5438844 | F7: ocp90bdzb4 | G7: https://offcampus.dasa.ncsu.edu/housing/property/brick-bungalow-close-to-campus/ocp90bdzb4
A8: FURNISHED TOWNHOME RENTAL – 10 Mins to NCSU - 3 Bedroom - starting $750 per room | B8: 750 | C8: 750 | D8: =(B8+C8)/2 | E8: 4.0727304 | F8: ocpwwwe8yh | G8: https://offcampus.dasa.ncsu.edu/housing/property/furnished-townhome-rental-10-mins-to-ncsu-3-bedroom-starting-750-per-room/ocpwwwe8yh
A9: Great value in beautiful SW Raleigh | B9: 850 | C9: 850 | D9: =(B9+C9)/2 | E9: 3.4947692 | F9: ocp0gblz91 | G9: https://offcampus.dasa.ncsu.edu/housing/property/great-value-in-beautiful-sw-raleigh/ocp0gblz91
A10: Liberty station male only townhome- 5 miles from Centennial | B10: 900 | C10: 900 | D10: =(B10+C10)/2 | E10: 4.0649537 | F10: ocp2k0px98 | G10: https://offcampus.dasa.ncsu.edu/housing/property/liberty-station-male-only-townhome-5-miles-from-centennial/ocp2k0px98
A11: Room in House on Joyner Pl | B11: 700 | C11: 700 | D11: =(B11+C11)/2 | E11: 4.5165241 | F11: jkg82q6 | G11: https://offcampus.dasa.ncsu.edu/housing/property/room-in-house-on-joyner-pl/jkg82q6
A12: Room in House on Quartz Ct | B12: 685 | C12: 685 | D12: =(B12+C12)/2 | E12: 4.7306191 | F12: bq6wzsb | G12: https://offcampus.dasa.ncsu.edu/housing/property/room-in-house-on-quartz-ct/bq6wzsb
A13: Room in Townhome on Haskell Dr | B13: 563 | C13: 563 | D13: =(B13+C13)/2 | E13: 4.0673108 | F13: 49jmmdh | G13: https://offcampus.dasa.ncsu.edu/housing/property/room-in-townhome-on-haskell-dr/49jmmdh
A14: Room in Townhome on Macedonia Lake Dr | B14: 800 | C14: 800 | D14: =(B14+C14)/2 | E14: 4.036728 | F14: 9m73sq5 | G14: https://offcampus.dasa.ncsu.edu/housing/property/room-in-townhome-on-macedonia-lake-dr/9m73sq5
A16: Prices used (COUNT) | B16: =COUNT(B5:B14) | C16: =COUNT(C5:C14) | D16: =COUNT(D5:D14)
A17: Total advertised rent (SUM) | B17: =SUM(B5:B14) | C17: =SUM(C5:C14) | D17: =SUM(D5:D14)
A18: Average (sum / count) | B18: =B17/B16 | C18: =C17/C16 | D18: =D17/D16
A19: Median listing midpoint | D19: =MEDIAN(D5:D14)

Sheet Centennial all bands (74)
A1: Centennial Campus all three bands — 74 room listings
A2: Sept. 9, 2026 advertised-price snapshot. Exact Centennial Campus all-bands view used to verify the article interactive. One vote per listing; midpoint=(low+high)/2.
A4: Listing name | B4: Low ($/month) | C4: High ($/month) | D4: Midpoint ($/month) | E4: Distance (mi) | F4: Band | G4: Listing ID | H4: Source URL
A5: "Avery Close " condos room available across from Centennial Campus NCSU NC State Raleigh | B5: 750 | C5: 750 | D5: =(B5+C5)/2 | E5: 0.47290191 | F5: 0-1 mi | G5: ocpsnmx4w4 | H5: https://offcampus.dasa.ncsu.edu/housing/property/avery-close-condos-room-available-across-from-centennial-campus-ncsu-nc-state-raleigh/ocpsnmx4w4
A6: 4BR/4BA Condo| On Wolfline | Preleasing 27-28 Special $850 Util/Parking Incld | Mile to Campus | B6: 875 | C6: 875 | D6: =(B6+C6)/2 | E6: 0.79954252 | F6: 0-1 mi | G6: ocpxdxd79p | H6: https://offcampus.dasa.ncsu.edu/housing/property/4br-4ba-condo-on-wolfline-preleasing-27-28-special-850-util-parking-incld-mile-to-campus/ocpxdxd79p
A7: Big Promotion w/best price ever. Move in Immediately . MarcomTowns. Great location nice | B7: 950 | C7: 950 | D7: =(B7+C7)/2 | E7: 0.86708054 | F7: 0-1 mi | G7: ocpe1n95cm | H7: https://offcampus.dasa.ncsu.edu/housing/property/big-promotion-w-best-price-ever-move-in-immediately-marcomtowns-great-location-nice/ocpe1n95cm
A8: Burt Drive Townhouses---Brand New Luxury Housing within walking distance to NCSU | B8: 1050 | C8: 1050 | D8: =(B8+C8)/2 | E8: 0.70283692 | F8: 0-1 mi | G8: ocpm68s5sh | H8: https://offcampus.dasa.ncsu.edu/housing/property/burt-drive-townhouses-brand-new-luxury-housing-within-walking-distance-to-ncsu/ocpm68s5sh
A9: College Inn | B9: 859 | C9: 1275 | D9: =(B9+C9)/2 | E9: 0.81855113 | F9: 0-1 mi | G9: se736e5 | H9: https://offcampus.dasa.ncsu.edu/housing/property/college-inn/se736e5
A10: Collegeview Duplex--Brand New Luxury Housing within walking distance to NCSU | B10: 900 | C10: 950 | D10: =(B10+C10)/2 | E10: 0.76469243 | F10: 0-1 mi | G10: ocppjxdd3r | H10: https://offcampus.dasa.ncsu.edu/housing/property/collegeview-duplex-brand-new-luxury-housing-within-walking-distance-to-ncsu/ocppjxdd3r
A11: Convenient Kaplan Dr property near NCSU buses, park, grocery, with parking space & private bathroom | B11: 675 | C11: 675 | D11: =(B11+C11)/2 | E11: 0.96777488 | F11: 0-1 mi | G11: ocp5lwrmvq | H11: https://offcampus.dasa.ncsu.edu/housing/property/convenient-kaplan-dr-property-near-ncsu-buses-park-grocery-with-parking-space-and-private-bathroom/ocp5lwrmvq
A12: Spacious bedroom with private bath in 2BR townhome – 5 minutes to NC State | B12: 800 | C12: 800 | D12: =(B12+C12)/2 | E12: 0.85260299 | F12: 0-1 mi | G12: ocpszex2v4 | H12: https://offcampus.dasa.ncsu.edu/housing/property/spacious-bedroom-with-private-bath-in-2br-townhome-5-minutes-to-nc-state/ocpszex2v4
A13: $3600 saving on 2*2 Sublet at Stanhope Apartment for NC STATE | B13: 550 | C13: 550 | D13: =(B13+C13)/2 | E13: 1.4122983 | F13: 1-3 mi | G13: ocpd9wnxdk | H13: https://offcampus.dasa.ncsu.edu/housing/property/3600-saving-on-2-2-sublet-at-stanhope-apartment-for-nc-state/ocpd9wnxdk
A14: 105 Friendly Drive! Furnished Room Rentals with Utilities! | B14: 775 | C14: 1050 | D14: =(B14+C14)/2 | E14: 1.4083454 | F14: 1-3 mi | G14: ocphdtdgk2 | H14: https://offcampus.dasa.ncsu.edu/housing/property/105-friendly-drive-furnished-room-rentals-with-utilities/ocphdtdgk2
A15: 1st Month FREE! | B15: 625 | C15: 625 | D15: =(B15+C15)/2 | E15: 1.6433486 | F15: 1-3 mi | G15: ocpq292qyw | H15: https://offcampus.dasa.ncsu.edu/housing/property/1st-month-free/ocpq292qyw
A16: 4bed 4bath Apartment Near Centennial Campus | B16: 725 | C16: 725 | D16: =(B16+C16)/2 | E16: 1.3866242 | F16: 1-3 mi | G16: ocpsq86tm4 | H16: https://offcampus.dasa.ncsu.edu/housing/property/4bed-4bath-apartment-near-centennial-campus/ocpsq86tm4
... A78: Room in Townhome on Macedonia Lake Dr | B78: 800 | C78: 800 | D78: =(B78+C78)/2 | E78: 3.9104878 | F78: 3-5 mi | G78: 9m73sq5 | H78: https://offcampus.dasa.ncsu.edu/housing/property/room-in-townhome-on-macedonia-lake-dr/9m73sq5
A81: Prices used (COUNT) | B81: =COUNT(B5:B78) | C81: =COUNT(C5:C78) | D81: =COUNT(D5:D78)
A82: Total advertised rent (SUM) | B82: =SUM(B5:B78) | C82: =SUM(C5:C78) | D82: =SUM(D5:D78)
A83: Average (sum / count) | B83: =B82/B81 | C83: =C82/C81 | D83: =D82/D81
A84: Median listing midpoint | D84: =MEDIAN(D5:D78)
A87: Centennial Campus band | B87: Listings | C87: Low-price sum | D87: High-price sum | E87: Midpoint sum | F87: Mean midpoint
A88: 0-1 mi | B88: =COUNTIF($F$5:$F78,A88) | C88: =SUMIF($F$5:$F78,A88,$B$5:$B78) | D88: =SUMIF($F$5:$F78,A88,$C$5:$C78) | E88: =SUMIF($F$5:$F78,A88,$D$5:$D78) | F88: =E88/B88
A89: 1-3 mi | B89: =COUNTIF($F$5:$F78,A89) | C89: =SUMIF($F$5:$F78,A89,$B$5:$B78) | D89: =SUMIF($F$5:$F78,A89,$C$5:$C78) | E89: =SUMIF($F$5:$F78,A89,$D$5:$D78) | F89: =E89/B89
A90: 3-5 mi | B90: =COUNTIF($F$5:$F78,A90) | C90: =SUMIF($F$5:$F78,A90,$B$5:$B78) | D90: =SUMIF($F$5:$F78,A90,$C$5:$C78) | E90: =SUMIF($F$5:$F78,A90,$D$5:$D78) | F90: =E90/B90
A91: All three bands | B91: =SUM(B88:B90) | C91: =SUM(C88:C90) | D91: =SUM(D88:D90) | E91: =SUM(E88:E90) | F91: =E91/B91
A94: Draft page check | B94: Rounded average low | C94: Rounded average high | D94: Rounded midpoint
A95: Displayed values | B95: =ROUND(B83,0) | C95: =ROUND(C83,0) | D95: =ROUND(D83,0)

Sheet Centennial 0-1 mi
A1: Centennial 0-1 mi
A2: Sept. 9, 2026 advertised-price snapshot. One vote per listing; midpoint=(low+high)/2.
A4: Listing name | B4: Low ($/month) | C4: High ($/month) | D4: Midpoint ($/month) | E4: Distance (mi) | F4: Listing ID | G4: Source URL
A5: "Avery Close " condos room available across from Centennial Campus NCSU NC State Raleigh | B5: 750 | C5: 750 | D5: =(B5+C5)/2 | E5: 0.47290191 | F5: ocpsnmx4w4 | G5: https://offcampus.dasa.ncsu.edu/housing/property/avery-close-condos-room-available-across-from-centennial-campus-ncsu-nc-state-raleigh/ocpsnmx4w4
A6: 4BR/4BA Condo| On Wolfline | Preleasing 27-28 Special $850 Util/Parking Incld | Mile to Campus | B6: 875 | C6: 875 | D6: =(B6+C6)/2 | E6: 0.79954252 | F6: ocpxdxd79p | G6: https://offcampus.dasa.ncsu.edu/housing/property/4br-4ba-condo-on-wolfline-preleasing-27-28-special-850-util-parking-incld-mile-to-campus/ocpxdxd79p
A7: Big Promotion w/best price ever. Move in Immediately . MarcomTowns. Great location nice | B7: 950 | C7: 950 | D7: =(B7+C7)/2 | E7: 0.86708054 | F7: ocpe1n95cm | G7: https://offcampus.dasa.ncsu.edu/housing/property/big-promotion-w-best-price-ever-move-in-immediately-marcomtowns-great-location-nice/ocpe1n95cm
A8: Burt Drive Townhouses---Brand New Luxury Housing within walking distance to NCSU | B8: 1050 | C8: 1050 | D8: =(B8+C8)/2 | E8: 0.70283692 | F8: ocpm68s5sh | G8: https://offcampus.dasa.ncsu.edu/housing/property/burt-drive-townhouses-brand-new-luxury-housing-within-walking-distance-to-ncsu/ocpm68s5sh
A9: College Inn | B9: 859 | C9: 1275 | D9: =(B9+C9)/2 | E9: 0.81855113 | F9: se736e5 | G9: https://offcampus.dasa.ncsu.edu/housing/property/college-inn/se736e5
A10: Collegeview Duplex--Brand New Luxury Housing within walking distance to NCSU | B10: 900 | C10: 950 | D10: =(B10+C10)/2 | E10: 0.76469243 | F10: ocppjxdd3r | G10: https://offcampus.dasa.ncsu.edu/housing/property/collegeview-duplex-brand-new-luxury-housing-within-walking-distance-to-ncsu/ocppjxdd3r
A11: Convenient Kaplan Dr property near NCSU buses, park, grocery, with parking space & private bathroom | B11: 675 | C11: 675 | D11: =(B11+C11)/2 | E11: 0.96777488 | F11: ocp5lwrmvq | G11: https://offcampus.dasa.ncsu.edu/housing/property/convenient-kaplan-dr-property-near-ncsu-buses-park-grocery-with-parking-space-and-private-bathroom/ocp5lwrmvq
A12: Spacious bedroom with private bath in 2BR townhome – 5 minutes to NC State | B12: 800 | C12: 800 | D12: =(B12+C12)/2 | E12: 0.85260299 | F12: ocpszex2v4 | G12: https://offcampus.dasa.ncsu.edu/housing/property/spacious-bedroom-with-private-bath-in-2br-townhome-5-minutes-to-nc-state/ocpszex2v4
A14: Prices used (COUNT) | B14: =COUNT(B5:B12) | C14: =COUNT(C5:C12) | D14: =COUNT(D5:D12)
A15: Total advertised rent (SUM) | B15: =SUM(B5:B12) | C15: =SUM(C5:C12) | D15: =SUM(D5:D12)
A16: Average (sum / count) | B16: =B15/B14 | C16: =C15/C14 | D16: =D15/D14
A17: Median listing midpoint | D17: =MEDIAN(D5:D12)

Sheet Centennial 1-3 mi
A1: Centennial 1-3 mi
A2: Sept. 9, 2026 advertised-price snapshot. One vote per listing; midpoint=(low+high)/2.
A4: Listing name | B4: Low ($/month) | C4: High ($/month) | D4: Midpoint ($/month) | E4: Distance (mi) | F4: Listing ID | G4: Source URL
A5: $3600 saving on 2*2 Sublet at Stanhope Apartment for NC STATE | B5: 550 | C5: 550 | D5: =(B5+C5)/2 | E5: 1.4122983 | F5: ocpd9wnxdk | G5: https://offcampus.dasa.ncsu.edu/housing/property/3600-saving-on-2-2-sublet-at-stanhope-apartment-for-nc-state/ocpd9wnxdk
A6: 105 Friendly Drive! Furnished Room Rentals with Utilities! | B6: 775 | C6: 1050 | D6: =(B6+C6)/2 | E6: 1.4083454 | F6: ocphdtdgk2 | G6: https://offcampus.dasa.ncsu.edu/housing/property/105-friendly-drive-furnished-room-rentals-with-utilities/ocphdtdgk2
A7: 1st Month FREE! | B7: 625 | C7: 625 | D7: =(B7+C7)/2 | E7: 1.6433486 | F7: ocpq292qyw | G7: https://offcampus.dasa.ncsu.edu/housing/property/1st-month-free/ocpq292qyw
A8: 4bed 4bath Apartment Near Centennial Campus | B8: 725 | C8: 725 | D8: =(B8+C8)/2 | E8: 1.3866242 | F8: ocpsq86tm4 | G8: https://offcampus.dasa.ncsu.edu/housing/property/4bed-4bath-apartment-near-centennial-campus/ocpsq86tm4
A9: 5 bedroom townhome available near NC State | B9: 650 | C9: 650 | D9: =(B9+C9)/2 | E9: 1.6710459 | F9: ocppbmmgnt | G9: https://offcampus.dasa.ncsu.edu/housing/property/5-bedroom-townhome-available-near-nc-state/ocppbmmgnt
A10: Affordable Student Housing 1 Block from Campus on Wolf Line | B10: 640 | C10: 640 | D10: =(B10+C10)/2 | E10: 1.1557715 | F10: ocph8n0fc0 | G10: https://offcampus.dasa.ncsu.edu/housing/property/affordable-student-housing-1-block-from-campus-on-wolf-line/ocph8n0fc0
A11: All Girls Unit - Room with Private Bathroom at University Woods at Centennial Condominiums | B11: 645 | C11: 645 | D11: =(B11+C11)/2 | E11: 1.6182313 | F11: ocpjeweyz6 | G11: https://offcampus.dasa.ncsu.edu/housing/property/all-girls-unit-room-with-private-bathroom-at-university-woods-at-centennial-condominiums/ocpjeweyz6
A12: An apartments with 3 bed and 3 bath for NC State Students www.ncstudentsliving.com | B12: 650 | C12: 650 | D12: =(B12+C12)/2 | E12: 1.7197015 | F12: ocp0psn632 | G12: https://offcampus.dasa.ncsu.edu/housing/property/an-apartments-with-3-bed-and-3-bath-for-nc-state-students-www-ncstudentsliving-com/ocp0psn632
A13: Apartment close to NCSU | B13: 645 | C13: 645 | D13: =(B13+C13)/2 | E13: 1.4570636 | F13: ocpq99qjpx | G13: https://offcampus.dasa.ncsu.edu/housing/property/apartment-close-to-ncsu/ocpq99qjpx
A14: Brickside | B14: 999 | C14: 1825 | D14: =(B14+C14)/2 | E14: 1.430929 | F14: 75medjw | G14: https://offcampus.dasa.ncsu.edu/housing/property/brickside/75medjw
A15: Campus Crossings Raleigh | B15: 685 | C15: 870 | D15: =(B15+C15)/2 | E15: 1.7442024 | F15: z8cfdjw | G15: https://offcampus.dasa.ncsu.edu/housing/property/campus-crossings-raleigh/z8cfdjw
A16: Campus Crossings Raleigh | B16: 865 | C16: 865 | D16: =(B16+C16)/2 | E16: 1.7093793 | F16: ocp176ghy4 | G16: https://offcampus.dasa.ncsu.edu/housing/property/campus-crossings-raleigh/ocp176ghy4
... A57: We have 1 bedroom open In a luxury 5 bed 5 full bath house 1/1/27-6/30/27 | B57: 1200 | C57: 1200 | D57: =(B57+C57)/2 | E57: 2.1801041 | F57: ocp6wsb4yt | G57: https://offcampus.dasa.ncsu.edu/housing/property/we-have-1-bedroom-open-in-a-luxury-5-bed-5-full-bath-house-1-1-27-6-30-27/ocp6wsb4yt
A59: Prices used (COUNT) | B59: =COUNT(B5:B57) | C59: =COUNT(C5:C57) | D59: =COUNT(D5:D57)
A60: Total advertised rent (SUM) | B60: =SUM(B5:B57) | C60: =SUM(C5:C57) | D60: =SUM(D5:D57)
A61: Average (sum / count) | B61: =B60/B59 | C61: =C60/C59 | D61: =D60/D59
A62: Median listing midpoint | D62: =MEDIAN(D5:D57)

Sheet Centennial 3-5 mi
A1: Centennial 3-5 mi
A2: Sept. 9, 2026 advertised-price snapshot. One vote per listing; midpoint=(low+high)/2.
A4: Listing name | B4: Low ($/month) | C4: High ($/month) | D4: Midpoint ($/month) | E4: Distance (mi) | F4: Listing ID | G4: Source URL
A5: 2850 Sanderford Rd (Raleigh, NC) | B5: 650 | C5: 650 | D5: =(B5+C5)/2 | E5: 4.1755475 | F5: lpl9fce | G5: https://offcampus.dasa.ncsu.edu/housing/property/2850-sanderford-rd-raleigh-nc/lpl9fce
A6: Brand New Luxury Furnished Townhome | 4 Bed / 3.5 Bath | 5 Min to NC State & 3 Mins to Fenton +shop | B6: 900 | C6: 1050 | D6: =(B6+C6)/2 | E6: 3.5789267 | F6: ocpw46rjcl | G6: https://offcampus.dasa.ncsu.edu/housing/property/brand-new-luxury-furnished-townhome-4-bed-3-5-bath-5-min-to-nc-state-and-3-mins-to-fenton-shop/ocpw46rjcl
A7: Brick Bungalow close to Campus | B7: 1050 | C7: 1050 | D7: =(B7+C7)/2 | E7: 3.8072287 | F7: ocp90bdzb4 | G7: https://offcampus.dasa.ncsu.edu/housing/property/brick-bungalow-close-to-campus/ocp90bdzb4
A8: FURNISHED TOWNHOME RENTAL – 10 Mins to NCSU - 3 Bedroom - starting $750 per room | B8: 750 | C8: 750 | D8: =(B8+C8)/2 | E8: 3.4134184 | F8: ocpwwwe8yh | G8: https://offcampus.dasa.ncsu.edu/housing/property/furnished-townhome-rental-10-mins-to-ncsu-3-bedroom-starting-750-per-room/ocpwwwe8yh
A9: Great value in beautiful SW Raleigh | B9: 850 | C9: 850 | D9: =(B9+C9)/2 | E9: 3.2810364 | F9: ocp0gblz91 | G9: https://offcampus.dasa.ncsu.edu/housing/property/great-value-in-beautiful-sw-raleigh/ocp0gblz91
A10: Huge modern studio suite- private entrance and beth- near NCSU | B10: 1150 | C10: 1150 | D10: =(B10+C10)/2 | E10: 3.7188867 | F10: ocpteqgjg8 | G10: https://offcampus.dasa.ncsu.edu/housing/property/huge-modern-studio-suite-private-entrance-and-beth-near-ncsu/ocpteqgjg8
A11: Liberty station male only townhome- 5 miles from Centennial | B11: 900 | C11: 900 | D11: =(B11+C11)/2 | E11: 3.3906908 | F11: ocp2k0px98 | G11: https://offcampus.dasa.ncsu.edu/housing/property/liberty-station-male-only-townhome-5-miles-from-centennial/ocp2k0px98
A12: Paloma Raleigh | B12: 749 | C12: 1599 | D12: =(B12+C12)/2 | E12: 3.0600966 | F12: 0smdl31 | G12: https://offcampus.dasa.ncsu.edu/housing/property/paloma-raleigh/0smdl31
A13: Redpoint Raleigh | B13: 899 | C13: 995 | D13: =(B13+C13)/2 | E13: 3.1271753 | F13: 5x5ph7m | G13: https://offcampus.dasa.ncsu.edu/housing/property/redpoint-raleigh/5x5ph7m
A14: Room in House on Quartz Ct | B14: 685 | C14: 685 | D14: =(B14+C14)/2 | E14: 4.2004719 | F14: bq6wzsb | G14: https://offcampus.dasa.ncsu.edu/housing/property/room-in-house-on-quartz-ct/bq6wzsb
A15: Room in House on Slippery Elm Dr | B15: 720 | C15: 720 | D15: =(B15+C15)/2 | E15: 4.8835991 | F15: 3zb9brd | G15: https://offcampus.dasa.ncsu.edu/housing/property/room-in-house-on-slippery-elm-dr/3zb9brd
A16: Room in Townhome on Haskell Dr | B16: 563 | C16: 563 | D16: =(B16+C16)/2 | E16: 3.4031309 | F16: 49jmmdh | G16: https://offcampus.dasa.ncsu.edu/housing/property/room-in-townhome-on-haskell-dr/49jmmdh
A17: Room in Townhome on Macedonia Lake Dr | B17: 800 | C17: 800 | D17: =(B17+C17)/2 | E17: 3.9104878 | F17: 9m73sq5 | G17: https://offcampus.dasa.ncsu.edu/housing/property/room-in-townhome-on-macedonia-lake-dr/9m73sq5
A19: Prices used (COUNT) | B19: =COUNT(B5:B17) | C19: =COUNT(C5:C17) | D19: =COUNT(D5:D17)
A20: Total advertised rent (SUM) | B20: =SUM(B5:B17) | C20: =SUM(C5:C17) | D20: =SUM(D5:D17)
A21: Average (sum / count) | B21: =B20/B19 | C21: =C20/C19 | D21: =D20/D19
A22: Median listing midpoint | D22: =MEDIAN(D5:D17)

Sheet Biomedical all bands (70)
A1: Biomedical Campus all three bands — 70 room listings
A2: Sept. 9, 2026 advertised-price snapshot. Exact Biomedical Campus all-bands view used to verify the article interactive. One vote per listing; midpoint=(low+high)/2.
A4: Listing name | B4: Low ($/month) | C4: High ($/month) | D4: Midpoint ($/month) | E4: Distance (mi) | F4: Band | G4: Listing ID | H4: Source URL
A5: Room in House on Pineland Cir | B5: 700 | C5: 700 | D5: =(B5+C5)/2 | E5: 0.7467834 | F5: 0-1 mi | G5: x5wd0zn | H5: https://offcampus.dasa.ncsu.edu/housing/property/room-in-house-on-pineland-cir/x5wd0zn
A6: The Station | B6: 969 | C6: 969 | D6: =(B6+C6)/2 | E6: 0.43115555 | F6: 0-1 mi | G6: ocp2gxtxqc | H6: https://offcampus.dasa.ncsu.edu/housing/property/the-station/ocp2gxtxqc
A7: The Station Raleigh | B7: 749 | C7: 1930 | D7: =(B7+C7)/2 | E7: 0.40974186 | F7: 0-1 mi | G7: 5hme2mn | H7: https://offcampus.dasa.ncsu.edu/housing/property/the-station-raleigh/5hme2mn
A8: We have 1 bedroom open In a luxury 5 bed 5 full bath house 1/1/27-6/30/27 | B8: 1200 | C8: 1200 | D8: =(B8+C8)/2 | E8: 0.87090415 | F8: 0-1 mi | G8: ocp6wsb4yt | H8: https://offcampus.dasa.ncsu.edu/housing/property/we-have-1-bedroom-open-in-a-luxury-5-bed-5-full-bath-house-1-1-27-6-30-27/ocp6wsb4yt
A9: "Avery Close " condos room available across from Centennial Campus NCSU NC State Raleigh | B9: 750 | C9: 750 | D9: =(B9+C9)/2 | E9: 2.067124 | F9: 1-3 mi | G9: ocpsnmx4w4 | H9: https://offcampus.dasa.ncsu.edu/housing/property/avery-close-condos-room-available-across-from-centennial-campus-ncsu-nc-state-raleigh/ocpsnmx4w4
A10: $3600 saving on 2*2 Sublet at Stanhope Apartment for NC STATE | B10: 550 | C10: 550 | D10: =(B10+C10)/2 | E10: 1.6148627 | F10: 1-3 mi | G10: ocpd9wnxdk | H10: https://offcampus.dasa.ncsu.edu/housing/property/3600-saving-on-2-2-sublet-at-stanhope-apartment-for-nc-state/ocpd9wnxdk
A11: 105 Friendly Drive! Furnished Room Rentals with Utilities! | B11: 775 | C11: 1050 | D11: =(B11+C11)/2 | E11: 1.7092324 | F11: 1-3 mi | G11: ocphdtdgk2 | H11: https://offcampus.dasa.ncsu.edu/housing/property/105-friendly-drive-furnished-room-rentals-with-utilities/ocphdtdgk2
A12: 4bed 4bath Apartment Near Centennial Campus | B12: 725 | C12: 725 | D12: =(B12+C12)/2 | E12: 2.4737945 | F12: 1-3 mi | G12: ocpsq86tm4 | H12: https://offcampus.dasa.ncsu.edu/housing/property/4bed-4bath-apartment-near-centennial-campus/ocpsq86tm4
A13: 4BR/4BA Condo| On Wolfline | Preleasing 27-28 Special $850 Util/Parking Incld | Mile to Campus | B13: 875 | C13: 875 | D13: =(B13+C13)/2 | E13: 1.8941953 | F13: 1-3 mi | G13: ocpxdxd79p | H13: https://offcampus.dasa.ncsu.edu/housing/property/4br-4ba-condo-on-wolfline-preleasing-27-28-special-850-util-parking-incld-mile-to-campus/ocpxdxd79p
A14: Affordable Student Housing 1 Block from Campus on Wolf Line | B14: 640 | C14: 640 | D14: =(B14+C14)/2 | E14: 1.3891877 | F14: 1-3 mi | G14: ocph8n0fc0 | H14: https://offcampus.dasa.ncsu.edu/housing/property/affordable-student-housing-1-block-from-campus-on-wolf-line/ocph8n0fc0
A15: Apartment close to NCSU | B15: 645 | C15: 645 | D15: =(B15+C15)/2 | E15: 2.4937706 | F15: 1-3 mi | G15: ocpq99qjpx | H15: https://offcampus.dasa.ncsu.edu/housing/property/apartment-close-to-ncsu/ocpq99qjpx
A16: Big Promotion w/best price ever. Move in Immediately . MarcomTowns. Great location nice | B16: 950 | C16: 950 | D16: =(B16+C16)/2 | E16: 1.6740045 | F16: 1-3 mi | G16: ocpe1n95cm | H16: https://offcampus.dasa.ncsu.edu/housing/property/big-promotion-w-best-price-ever-move-in-immediately-marcomtowns-great-location-nice/ocpe1n95cm
... A74: Voyager House | B74: 800 | C74: 800 | D74: =(B74+C74)/2 | E74: 3.531182 | F74: 3-5 mi | G74: ocpbhbkvy9 | H74: https://offcampus.dasa.ncsu.edu/housing/property/voyager-house/ocpbhbkvy9
A77: Prices used (COUNT) | B77: =COUNT(B5:B74) | C77: =COUNT(C5:C74) | D77: =COUNT(D5:D74)
A78: Total advertised rent (SUM) | B78: =SUM(B5:B74) | C78: =SUM(C5:C74) | D78: =SUM(D5:D74)
A79: Average (sum / count) | B79: =B78/B77 | C79: =C78/C77 | D79: =D78/D77
A80: Median listing midpoint | D80: =MEDIAN(D5:D74)
A83: Biomedical Campus band | B83: Listings | C83: Low-price sum | D83: High-price sum | E83: Midpoint sum | F83: Mean midpoint
A84: 0-1 mi | B84: =COUNTIF($F$5:$F74,A84) | C84: =SUMIF($F$5:$F74,A84,$B$5:$B74) | D84: =SUMIF($F$5:$F74,A84,$C$5:$C74) | E84: =SUMIF($F$5:$F74,A84,$D$5:$D74) | F84: =E84/B84
A85: 1-3 mi | B85: =COUNTIF($F$5:$F74,A85) | C85: =SUMIF($F$5:$F74,A85,$B$5:$B74) | D85: =SUMIF($F$5:$F74,A85,$C$5:$C74) | E85: =SUMIF($F$5:$F74,A85,$D$5:$D74) | F85: =E85/B85
A86: 3-5 mi | B86: =COUNTIF($F$5:$F74,A86) | C86: =SUMIF($F$5:$F74,A86,$B$5:$B74) | D86: =SUMIF($F$5:$F74,A86,$C$5:$C74) | E86: =SUMIF($F$5:$F74,A86,$D$5:$D74) | F86: =E86/B86
A87: All three bands | B87: =SUM(B84:B86) | C87: =SUM(C84:C86) | D87: =SUM(D84:D86) | E87: =SUM(E84:E86) | F87: =E87/B87
A90: Draft page check | B90: Rounded average low | C90: Rounded average high | D90: Rounded midpoint
A91: Displayed values | B91: =ROUND(B79,0) | C91: =ROUND(C79,0) | D91: =ROUND(D79,0)

Sheet Biomedical 0-1 mi
A1: Biomedical 0-1 mi
A2: Sept. 9, 2026 advertised-price snapshot. One vote per listing; midpoint=(low+high)/2.
A4: Listing name | B4: Low ($/month) | C4: High ($/month) | D4: Midpoint ($/month) | E4: Distance (mi) | F4: Listing ID | G4: Source URL
A5: Room in House on Pineland Cir | B5: 700 | C5: 700 | D5: =(B5+C5)/2 | E5: 0.7467834 | F5: x5wd0zn | G5: https://offcampus.dasa.ncsu.edu/housing/property/room-in-house-on-pineland-cir/x5wd0zn
A6: The Station | B6: 969 | C6: 969 | D6: =(B6+C6)/2 | E6: 0.43115555 | F6: ocp2gxtxqc | G6: https://offcampus.dasa.ncsu.edu/housing/property/the-station/ocp2gxtxqc
A7: The Station Raleigh | B7: 749 | C7: 1930 | D7: =(B7+C7)/2 | E7: 0.40974186 | F7: 5hme2mn | G7: https://offcampus.dasa.ncsu.edu/housing/property/the-station-raleigh/5hme2mn
A8: We have 1 bedroom open In a luxury 5 bed 5 full bath house 1/1/27-6/30/27 | B8: 1200 | C8: 1200 | D8: =(B8+C8)/2 | E8: 0.87090415 | F8: ocp6wsb4yt | G8: https://offcampus.dasa.ncsu.edu/housing/property/we-have-1-bedroom-open-in-a-luxury-5-bed-5-full-bath-house-1-1-27-6-30-27/ocp6wsb4yt
A10: Prices used (COUNT) | B10: =COUNT(B5:B8) | C10: =COUNT(C5:C8) | D10: =COUNT(D5:D8)
A11: Total advertised rent (SUM) | B11: =SUM(B5:B8) | C11: =SUM(C5:C8) | D11: =SUM(D5:D8)
A12: Average (sum / count) | B12: =B11/B10 | C12: =C11/C10 | D12: =D11/D10
A13: Median listing midpoint | D13: =MEDIAN(D5:D8)

Sheet Biomedical 1-3 mi
A1: Biomedical 1-3 mi
A2: Sept. 9, 2026 advertised-price snapshot. One vote per listing; midpoint=(low+high)/2.
A4: Listing name | B4: Low ($/month) | C4: High ($/month) | D4: Midpoint ($/month) | E4: Distance (mi) | F4: Listing ID | G4: Source URL
A5: "Avery Close " condos room available across from Centennial Campus NCSU NC State Raleigh | B5: 750 | C5: 750 | D5: =(B5+C5)/2 | E5: 2.067124 | F5: ocpsnmx4w4 | G5: https://offcampus.dasa.ncsu.edu/housing/property/avery-close-condos-room-available-across-from-centennial-campus-ncsu-nc-state-raleigh/ocpsnmx4w4
A6: $3600 saving on 2*2 Sublet at Stanhope Apartment for NC STATE | B6: 550 | C6: 550 | D6: =(B6+C6)/2 | E6: 1.6148627 | F6: ocpd9wnxdk | G6: https://offcampus.dasa.ncsu.edu/housing/property/3600-saving-on-2-2-sublet-at-stanhope-apartment-for-nc-state/ocpd9wnxdk
A7: 105 Friendly Drive! Furnished Room Rentals with Utilities! | B7: 775 | C7: 1050 | D7: =(B7+C7)/2 | E7: 1.7092324 | F7: ocphdtdgk2 | G7: https://offcampus.dasa.ncsu.edu/housing/property/105-friendly-drive-furnished-room-rentals-with-utilities/ocphdtdgk2
A8: 4bed 4bath Apartment Near Centennial Campus | B8: 725 | C8: 725 | D8: =(B8+C8)/2 | E8: 2.4737945 | F8: ocpsq86tm4 | G8: https://offcampus.dasa.ncsu.edu/housing/property/4bed-4bath-apartment-near-centennial-campus/ocpsq86tm4
A9: 4BR/4BA Condo| On Wolfline | Preleasing 27-28 Special $850 Util/Parking Incld | Mile to Campus | B9: 875 | C9: 875 | D9: =(B9+C9)/2 | E9: 1.8941953 | F9: ocpxdxd79p | G9: https://offcampus.dasa.ncsu.edu/housing/property/4br-4ba-condo-on-wolfline-preleasing-27-28-special-850-util-parking-incld-mile-to-campus/ocpxdxd79p
A10: Affordable Student Housing 1 Block from Campus on Wolf Line | B10: 640 | C10: 640 | D10: =(B10+C10)/2 | E10: 1.3891877 | F10: ocph8n0fc0 | G10: https://offcampus.dasa.ncsu.edu/housing/property/affordable-student-housing-1-block-from-campus-on-wolf-line/ocph8n0fc0
A11: Apartment close to NCSU | B11: 645 | C11: 645 | D11: =(B11+C11)/2 | E11: 2.4937706 | F11: ocpq99qjpx | G11: https://offcampus.dasa.ncsu.edu/housing/property/apartment-close-to-ncsu/ocpq99qjpx
A12: Big Promotion w/best price ever. Move in Immediately . MarcomTowns. Great location nice | B12: 950 | C12: 950 | D12: =(B12+C12)/2 | E12: 1.6740045 | F12: ocpe1n95cm | G12: https://offcampus.dasa.ncsu.edu/housing/property/big-promotion-w-best-price-ever-move-in-immediately-marcomtowns-great-location-nice/ocpe1n95cm
A13: Brand New Luxury Furnished Townhome | 4 Bed / 3.5 Bath | 5 Min to NC State & 3 Mins to Fenton +shop | B13: 900 | C13: 1050 | D13: =(B13+C13)/2 | E13: 2.6317869 | F13: ocpw46rjcl | G13: https://offcampus.dasa.ncsu.edu/housing/property/brand-new-luxury-furnished-townhome-4-bed-3-5-bath-5-min-to-nc-state-and-3-mins-to-fenton-shop/ocpw46rjcl
A14: Brickside | B14: 999 | C14: 1825 | D14: =(B14+C14)/2 | E14: 2.04187 | F14: 75medjw | G14: https://offcampus.dasa.ncsu.edu/housing/property/brickside/75medjw
A15: Burt Drive Townhouses---Brand New Luxury Housing within walking distance to NCSU | B15: 1050 | C15: 1050 | D15: =(B15+C15)/2 | E15: 1.8446773 | F15: ocpm68s5sh | G15: https://offcampus.dasa.ncsu.edu/housing/property/burt-drive-townhouses-brand-new-luxury-housing-within-walking-distance-to-ncsu/ocpm68s5sh
A16: College Inn | B16: 859 | C16: 1275 | D16: =(B16+C16)/2 | E16: 1.938378 | F16: se736e5 | G16: https://offcampus.dasa.ncsu.edu/housing/property/college-inn/se736e5
... A42: Valentine Commons | B42: 1000 | C42: 1300 | D42: =(B42+C42)/2 | E42: 1.6585498 | F42: ocp5cx5drn | G42: https://offcampus.dasa.ncsu.edu/housing/property/valentine-commons/ocp5cx5drn
A44: Prices used (COUNT) | B44: =COUNT(B5:B42) | C44: =COUNT(C5:C42) | D44: =COUNT(D5:D42)
A45: Total advertised rent (SUM) | B45: =SUM(B5:B42) | C45: =SUM(C5:C42) | D45: =SUM(D5:D42)
A46: Average (sum / count) | B46: =B45/B44 | C46: =C45/C44 | D46: =D45/D44
A47: Median listing midpoint | D47: =MEDIAN(D5:D42)

Sheet Biomedical 3-5 mi
A1: Biomedical 3-5 mi
A2: Sept. 9, 2026 advertised-price snapshot. One vote per listing; midpoint=(low+high)/2.
A4: Listing name | B4: Low ($/month) | C4: High ($/month) | D4: Midpoint ($/month) | E4: Distance (mi) | F4: Listing ID | G4: Source URL
A5: 1st Month FREE! | B5: 625 | C5: 625 | D5: =(B5+C5)/2 | E5: 3.4623498 | F5: ocpq292qyw | G5: https://offcampus.dasa.ncsu.edu/housing/property/1st-month-free/ocpq292qyw
A6: 5 bedroom townhome available near NC State | B6: 650 | C6: 650 | D6: =(B6+C6)/2 | E6: 3.8377333 | F6: ocppbmmgnt | G6: https://offcampus.dasa.ncsu.edu/housing/property/5-bedroom-townhome-available-near-nc-state/ocppbmmgnt
A7: All Girls Unit - Room with Private Bathroom at University Woods at Centennial Condominiums | B7: 645 | C7: 645 | D7: =(B7+C7)/2 | E7: 3.4358504 | F7: ocpjeweyz6 | G7: https://offcampus.dasa.ncsu.edu/housing/property/all-girls-unit-room-with-private-bathroom-at-university-woods-at-centennial-condominiums/ocpjeweyz6
A8: An apartments with 3 bed and 3 bath for NC State Students www.ncstudentsliving.com | B8: 650 | C8: 650 | D8: =(B8+C8)/2 | E8: 3.4494305 | F8: ocp0psn632 | G8: https://offcampus.dasa.ncsu.edu/housing/property/an-apartments-with-3-bed-and-3-bath-for-nc-state-students-www-ncstudentsliving-com/ocp0psn632
A9: Brick Bungalow close to Campus | B9: 1050 | C9: 1050 | D9: =(B9+C9)/2 | E9: 4.3183317 | F9: ocp90bdzb4 | G9: https://offcampus.dasa.ncsu.edu/housing/property/brick-bungalow-close-to-campus/ocp90bdzb4
A10: Campus Crossings Raleigh | B10: 685 | C10: 870 | D10: =(B10+C10)/2 | E10: 3.8220471 | F10: z8cfdjw | G10: https://offcampus.dasa.ncsu.edu/housing/property/campus-crossings-raleigh/z8cfdjw
A11: Campus Crossings Raleigh | B11: 865 | C11: 865 | D11: =(B11+C11)/2 | E11: 3.7623038 | F11: ocp176ghy4 | G11: https://offcampus.dasa.ncsu.edu/housing/property/campus-crossings-raleigh/ocp176ghy4
A12: Campus West at Tryon | B12: 699 | C12: 699 | D12: =(B12+C12)/2 | E12: 3.4653633 | F12: 0pm7tt3 | G12: https://offcampus.dasa.ncsu.edu/housing/property/campus-west-at-tryon/0pm7tt3
A13: Centennial Ridge Student Housing | B13: 599 | C13: 2157 | D13: =(B13+C13)/2 | E13: 3.7055217 | F13: 7e6kx1w | G13: https://offcampus.dasa.ncsu.edu/housing/property/centennial-ridge-student-housing/7e6kx1w
A14: Great value in beautiful SW Raleigh | B14: 850 | C14: 850 | D14: =(B14+C14)/2 | E14: 3.8171698 | F14: ocp0gblz91 | G14: https://offcampus.dasa.ncsu.edu/housing/property/great-value-in-beautiful-sw-raleigh/ocp0gblz91
A15: Hurry 2 Rooms Left! – 4BR/4BA Condo Near NC State – All Utilities & Internet Included! | B15: 695 | C15: 695 | D15: =(B15+C15)/2 | E15: 3.4388677 | F15: ocpchygggd | G15: https://offcampus.dasa.ncsu.edu/housing/property/hurry-2-rooms-left-4br-4ba-condo-near-nc-state-all-utilities-and-internet-included/ocpchygggd
A16: Newly Renovated - All Girls Unit Room with Private Bathroom | B16: 645 | C16: 645 | D16: =(B16+C16)/2 | E16: 3.3993822 | F16: ocp6mp93ms | G16: https://offcampus.dasa.ncsu.edu/housing/property/newly-renovated-all-girls-unit-room-with-private-bathroom/ocp6mp93ms
... A32: Voyager House | B32: 800 | C32: 800 | D32: =(B32+C32)/2 | E32: 3.531182 | F32: ocpbhbkvy9 | G32: https://offcampus.dasa.ncsu.edu/housing/property/voyager-house/ocpbhbkvy9
A34: Prices used (COUNT) | B34: =COUNT(B5:B32) | C34: =COUNT(C5:C32) | D34: =COUNT(D5:D32)
A35: Total advertised rent (SUM) | B35: =SUM(B5:B32) | C35: =SUM(C5:C32) | D35: =SUM(D5:D32)
A36: Average (sum / count) | B36: =B35/B34 | C36: =C35/C34 | D36: =D35/D34
A37: Median listing midpoint | D37: =MEDIAN(D5:D32)

Sheet Excluded
A1: Listing name | B1: Reviewed basis | C1: Reason excluded from room article | D1: Listing ID | E1: Source URL | F1: Review evidence
A2: $300 off 1st month's rent! Spacious 3BD/2.5BA Townhome Rental available near NCSU for fall semester! | B2: Whole unit | C2: Whole-unit offer, outside room-only scope. | D2: ocp5z7c91m | E2: https://offcampus.dasa.ncsu.edu/housing/property/300-off-1st-months-rent-spacious-3bd-2-5ba-townhome-rental-available-near-ncsu-for-fall-semester/ocp5z7c91m | F2: Source pricing flag retained; automated consistency checks passed. This is not independent landlord verification.
A3: ** WAITLIST for 2026-2027 ** 4 Bedroom, 4.5 Bathroom Unit Near NCSU Campus and Cup A Joe | B3: Whole unit | C3: Whole-unit offer, outside room-only scope. | D3: ocp913l1z6 | E3: https://offcampus.dasa.ncsu.edu/housing/property/waitlist-for-2026-2027-4-bedroom-4-5-bathroom-unit-near-ncsu-campus-and-cup-a-joe/ocp913l1z6 | F3: Source pricing flag retained; automated consistency checks passed. This is not independent landlord verification.
A4: 1101 Gunnison Pl (Raleigh, NC) | B4: Whole unit | C4: Whole-unit offer, outside room-only scope. | D4: 51px18q | E4: https://offcampus.dasa.ncsu.edu/housing/property/1101-gunnison-pl-raleigh-nc/51px18q | F4: Source pricing flag retained; automated consistency checks passed. This is not independent landlord verification.
A5: 1233 S Blount St (Raleigh, NC) | B5: Whole unit | C5: Search/detail price mismatch. Whole-unit offer, outside room-only scope. | D5: teq7kh8 | E5: https://offcampus.dasa.ncsu.edu/housing/property/1233-s-blount-st-raleigh-nc/teq7kh8 | F5: Source pricing flag retained; automated consistency checks passed. This is not independent landlord verification. Search summary: $3800–$3800; saved floor-plan envelope: $3000–$3000. Difference may reflect fees, timing or scope; unresolved snapshot price excluded.
A6: 1431 Collegiate Cir (Raleigh, NC) | B6: Whole unit | C6: Search/detail price mismatch. Whole-unit offer, outside room-only scope. | D6: qcvpeqz | E6: https://offcampus.dasa.ncsu.edu/housing/property/1431-collegiate-cir-raleigh-nc/qcvpeqz | F6: Source pricing flag retained; automated consistency checks passed. This is not independent landlord verification. Search summary: $750–$750; saved floor-plan envelope: $725–$725. Difference may reflect fees, timing or scope; unresolved snapshot price excluded.
A7: 2 blocks from central campus, 2 blocks from Village District! | B7: Whole unit | C7: Whole-unit offer, outside room-only scope. | D7: ocp1tnqde5 | E7: https://offcampus.dasa.ncsu.edu/housing/property/2-blocks-from-central-campus-2-blocks-from-village-district/ocp1tnqde5 | F7: Source pricing flag retained; automated consistency checks passed. This is not independent landlord verification.
A8: 2626 Wolf Cub Ct (Raleigh, NC) | B8: Whole unit | C8: Whole-unit offer, outside room-only scope. | D8: dnbdmqk | E8: https://offcampus.dasa.ncsu.edu/housing/property/2626-wolf-cub-ct-raleigh-nc/dnbdmqk | F8: Source pricing flag retained; automated consistency checks passed. This is not independent landlord verification.
A9: 2810 Crestscene Trail (Raleigh, NC) | B9: Whole unit | C9: Whole-unit offer, outside room-only scope. | D9: 6lbm6br | E9: https://offcampus.dasa.ncsu.edu/housing/property/2810-crestscene-trail-raleigh-nc/6lbm6br | F9: Source pricing flag retained; automated consistency checks passed. This is not independent landlord verification.
A10: 3 bedroom home close to campus and downtown Raleigh(Utilities included) | B10: Whole unit | C10: Whole-unit offer, outside room-only scope. | D10: ocpn54lxfn | E10: https://offcampus.dasa.ncsu.edu/housing/property/3-bedroom-home-close-to-campus-and-downtown-raleigh-utilities-included/ocpn54lxfn | F10: Source pricing flag retained; automated consistency checks passed. This is not independent landlord verification.
A11: 3111 Kentish Town Ln (Raleigh, NC) | B11: Whole unit | C11: Search/detail price mismatch. Whole-unit offer, outside room-only scope. | D11: gdtz0ww | E11: https://offcampus.dasa.ncsu.edu/housing/property/3111-kentish-town-ln-raleigh-nc/gdtz0ww | F11: Source pricing flag retained; automated consistency checks passed. This is not independent landlord verification. Search summary: $2700–$2700; saved floor-plan envelope: $2675–$2675. Difference may reflect fees, timing or scope; unresolved snapshot price excluded.
A12: 4BD/3.5BA townhome near NCSU & Downtown Raleigh available August 2026! | B12: Whole unit | C12: Whole-unit offer, outside room-only scope. | D12: ocpjh4j574 | E12: https://offcampus.dasa.ncsu.edu/housing/property/4bd-3-5ba-townhome-near-ncsu-and-downtown-raleigh-available-august-2026/ocpjh4j574 | F12: Source pricing flag retained; automated consistency checks passed. This is not independent landlord verification.
... A93: Yugo Raleigh Logan | B93: Review | C93: Unresolved pricing basis. Not a resolved room/per-bedroom offer. | D93: zfcjzqy | E93: https://offcampus.dasa.ncsu.edu/housing/property/yugo-raleigh-logan/zfcjzqy | F93: Saved floor plans contain both per-bedroom and whole-unit flags. A single property range cannot be assigned a reliable common pricing basis; no division by bedroom count or price substitution.

Sheet Listings
A1: Listing ID | B1: Listing name | C1: Source URL | D1: Reviewed basis | E1: Latitude | F1: Longitude | G1: Low ($/mo) | H1: High ($/mo) | I1: Midpoint ($/mo) | J1: Main distance (mi) | K1: Main band | L1: Centennial distance (mi) | M1: Centennial band | N1: Biomedical distance (mi) | O1: Biomedical band | P1: In union | Q1: Room audit | R1: Review status / reason
A2: kele8mc | B2: Lofts at Lakeview | C2: https://offcampus.dasa.ncsu.edu/housing/property/lofts-at-lakeview/kele8mc | D2: Whole unit | E2: 36.009311 | F2: -78.94637 | G2: 1595 | H2: 2995 | I2: =(G2+H2)/2 | J2: 21.716274 | K2: Outside 5 mi | L2: 22.425224 | M2: Outside 5 mi | N2: 19.902018 | O2: Outside 5 mi | P2: 0 | Q2: 0 | R2: Included in rent means | Source pricing flag retained; automated consistency checks passed. This is not independent landlord verification.
A3: ocpet5b7hm | B3: Modern/High Ceilings 2bed/2 bath | C3: https://offcampus.dasa.ncsu.edu/housing/property/modern-high-ceilings-2bed-2-bath/ocpet5b7hm | D3: Per bedroom | E3: 35.787311 | F3: -78.666093 | G3: 1250 | H3: 1250 | I3: =(G3+H3)/2 | J3: 1.026552 | K3: >1–3 mi | L3: 1.4361007 | M3: >1–3 mi | N3: 2.2642641 | O3: >1–3 mi | P3: 1 | Q3: 1 | R3: Included in rent means | Source pricing flag retained; automated consistency checks passed. This is not independent landlord verification.
A4: 59xvx3n | B4: Aventura RTP | C4: https://offcampus.dasa.ncsu.edu/housing/property/aventura-rtp/59xvx3n | D4: Whole unit | E4: 35.894098 | F4: -78.846917 | G4: 1149 | H4: 1946 | I4: =(G4+H4)/2 | J4: 12.179761 | K4: Outside 5 mi | L4: 12.850385 | M4: Outside 5 mi | N4: 10.375583 | O4: Outside 5 mi | P4: 0 | Q4: 0 | R4: Included in rent means | Source pricing flag retained; automated consistency checks passed. This is not independent landlord verification.
A5: ocpvcjy8we | B5: Rare 4 bedroom 4 full bath only $2200. per month | C5: https://offcampus.dasa.ncsu.edu/housing/property/rare-4-bedroom-4-full-bath-only-2200-per-month/ocpvcjy8we | D5: Whole unit | E5: 35.762584 | F5: -78.703352 | G5: 2200 | H5: 2200 | I5: =(G5+H5)/2 | J5: 1.6863307 | K5: >1–3 mi | L5: 1.509698 | M5: >1–3 mi | N5: 2.4798222 | O5: >1–3 mi | P5: 1 | Q5: 0 | R5: Included in rent means | Source pricing flag retained; automated consistency checks passed. This is not independent landlord verification.
A6: 7e6kx1w | B6: Centennial Ridge Student Housing | C6: https://offcampus.dasa.ncsu.edu/housing/property/centennial-ridge-student-housing/7e6kx1w | D6: Per bedroom | E6: 35.745958 | F6: -78.69065 | G6: 599 | H6: 2157 | I6: =(G6+H6)/2 | J6: 2.3721447 | K6: >1–3 mi | L6: 1.7357078 | M6: >1–3 mi | N6: 3.7055217 | O6: >3–5 mi | P6: 1 | Q6: 1 | R6: Included in rent means | Portal explicitly labels the entire $599–$2,157 range per bedroom (reviewed September 13). Retained as reported, but the high endpoint needs landlord confirmation. Sensitivity results also omit this listing; no assumed division by three.
A7: ocpw46rjcl | B7: Brand New Luxury Furnished Townhome | 4 Bed / 3.5 Bath | 5 Min to NC State & 3 Mins to Fenton +shop | C7: https://offcampus.dasa.ncsu.edu/housing/property/brand-new-luxury-furnished-townhome-4-bed-3-5-bath-5-min-to-nc-state-and-3-mins-to-fenton-shop/ocpw46rjcl | D7: Per bedroom | E7: 35.774826 | F7: -78.740894 | G7: 900 | H7: 1050 | I7: =(G7+H7)/2 | J7: 3.334997 | K7: >3–5 mi | L7: 3.5789267 | M7: >3–5 mi | N7: 2.6317869 | O7: >1–3 mi | P7: 1 | Q7: 1 | R7: Included in rent means | Source pricing flag retained; automated consistency checks passed. This is not independent landlord verification.
A8: mc0h4yh | B8: The Reserve at Patterson Place | C8: https://offcampus.dasa.ncsu.edu/housing/property/the-reserve-at-patterson-place/mc0h4yh | D8: Whole unit | E8: 35.950566 | F8: -78.983303 | G8: 1288 | H8: 2422 | I8: =(G8+H8)/2 | J8: 20.613532 | K8: Outside 5 mi | L8: 21.239844 | M8: Outside 5 mi | N8: 18.836598 | O8: Outside 5 mi | P8: 0 | Q8: 0 | R8: Excluded from rent means | Search/detail price mismatch | Source pricing flag retained; automated consistency checks passed. This is not independent landlord verification. Search summary: $1288–$2422; saved floor-plan envelope: $1238–$2422. Difference may reflect fees, timing or scope; unresolved snapshot price excluded.
A9: ocpchygggd | B9: Hurry 2 Rooms Left! – 4BR/4BA Condo Near NC State – All Utilities & Internet Included! | C9: https://offcampus.dasa.ncsu.edu/housing/property/hurry-2-rooms-left-4br-4ba-condo-near-nc-state-all-utilities-and-internet-included/ocpchygggd | D9: Per bedroom | E9: 35.749382 | F9: -78.69395 | G9: 695 | H9: 695 | I9: =(G9+H9)/2 | J9: 2.1923663 | K9: >1–3 mi | L9: 1.6224123 | M9: >1–3 mi | N9: 3.4388677 | O9: >3–5 mi | P9: 1 | Q9: 1 | R9: Included in rent means | Source pricing flag retained; automated consistency checks passed. This is not independent landlord verification.
A10: es0855q | B10: Maxwell Raleigh | C10: https://offcampus.dasa.ncsu.edu/housing/property/maxwell-raleigh/es0855q | D10: Review | E10: 35.78944 | F10: -78.678155 | G10: 799 | H10: 1899 | I10: =(G10+H10)/2 | J10: 0.71397936 | K10: 0–1 mi | L10: 1.4334678 | M10: >1–3 mi | N10: 1.5812218 | O10: >1–3 mi | P10: 1 | Q10: 0 | R10: Excluded from rent means | Unresolved pricing basis | Saved floor plans contain both per-bedroom and whole-unit flags. A single property range cannot be assigned a reliable common pricing basis; no division by bedroom count or price substitution.
A11: ocpesl9n3p | B11: maisonNC --- Fully Furnished minutes away from Wolfline and Shopping | C11: https://offcampus.dasa.ncsu.edu/housing/property/maisonnc-fully-furnished-minutes-away-from-wolfline-and-shopping/ocpesl9n3p | D11: Per bedroom | E11: 35.763398 | F11: -78.702658 | G11: 750 | H11: 750 | I11: =(G11+H11)/2 | J11: 1.6193494 | K11: >1–3 mi | L11: 1.4572334 | M11: >1–3 mi | N11: 2.4245549 | O11: >1–3 mi | P11: 1 | Q11: 1 | R11: Included in rent means | Source pricing flag retained; automated consistency checks passed. This is not independent landlord verification.
